Workbook

Sheet Assumptions
A1: THE GUARDIAN MVP - 12 MONTH MODEL
A2: BLUE CELLS = INPUTS YOU CAN CHANGE
A4: MEMBER ASSUMPTIONS
A5: Total Members (End of Year) | B5: 1000 | D5: Target member count
A6: Basic Tier % | B6: 0.7 | D6: 70% at $3.75/week
A7: Elite Tier % | B7: 0.3 | D7: 30% at $5.95/week
A8: Basic Weekly Rate ($) | B8: 3.75 | D8: Weekly subscription
A9: Elite Weekly Rate ($) | B9: 5.95 | D9: Weekly subscription
A10: Weeks per Month | B10: 4.33 | D10: Average
A12: ZŪM RAILS COSTS (per transaction)
A13: EFT Success | B13: 0.25 | D13: Debit pull for repayments
A14: Interac Send | B14: 1 | D14: e-Transfer out
A15: Interac ANR (Instant) | B15: 1.25 | D15: Instant rails
A16: Aggregation New User | B16: 0.3 | D16: Bank connection
A18: SERVICE USAGE (per member per month)
A19: Shield Saves Needed | B19: 0.8 | D19: 80% need NSF protection
A20: Milk Money Uses | B20: 0.6 | D20: 60% use micro-loans
A21: Payroll Accelerator Uses | B21: 0.3 | D21: 30% use early pay
A22: Check Bridge Uses | B22: 0.15 | D22: 15% use deposit release
A23: Lifeline Link Gifts | B23: 0.1 | D23: 10% give to neighbors
A24: Avg Transactions/Member | B24: 25 | D24: For Nickel Millionaire
A26: MILK MONEY PARAMETERS
A27: Average Loan Amount | B27: 60 | D27: Avg micro-loan size
A28: APR | B28: 0.0995 | D28: 9.95% annual rate
A29: Avg Days Outstanding | B29: 14 | D29: Two week average
A30: Bad Debt Rate | B30: 0.08 | D30: 8% default rate
A32: PRIVATE BANKER (PHILIPPINES)
A33: Monthly Cost per Agent | B33: 1000 | D33: Full-loaded cost
A34: Members per Agent | B34: 200 | D34: Caseload capacity
A35: Training Cost (one-time) | B35: 500 | D35: Per agent onboarding
A37: OTHER MONTHLY COSTS
A38: Tech Infrastructure | B38: 1500 | D38: Servers, APIs, software
A39: Compliance & Legal | B39: 500 | D39: Regulatory reserve
A40: Customer Support Buffer | B40: 300 | D40: Escalations
A42: LEAD GENERATION - TARGET: 1,000 NEW MEMBERS/MONTH
A43: Monthly New Member Target | B43: 1000 | D43: Acquisition goal
A44: Lead-to-Member Conversion Rate | B44: 0.25 | D44: 25% of leads become members
A45: Leads Needed per Month | B45: =B43/B44 -> 4000 | D45: Formula: Target/Conversion
A46: Selected Channel Cost per Lead | B46: 22 | D46: Facebook Ads CPL
A47: Referral Bonus per New Member | B47: 10 | D47: Paid to referrer
...

Sheet Lead Gen Options
A1: LEAD GENERATION OPTIONS FOR THE GUARDIAN
A2: Target: 1,000 new members/month | Market: Working Poor / Underbanked Canadians
A4: Channel | B4: Cost per Lead | C4: Conversion Rate | D4: Cost per Member | E4: Monthly Cost (1K members) | F4: Pros | G4: Cons
A5: Facebook/Meta Ads | B5: 22 | C5: 0.25 | D5: 88 | E5: 88000 | F5: Reaches working class well, visual storytelling, $11 CPM in Canada, lead forms native | G5: Requires creative refresh, compliance review needed
A6: Google Ads | B6: 70 | C6: 0.2 | D6: 350 | E6: 350000 | F6: High intent traffic, immediate visibility | G6: Expensive for financial services, restrictions on personal loans, cant target by income
A7: Member Referral Program | B7: 25 | C7: 0.5 | D7: 50 | E7: 50000 | F7: Highest quality leads, 53% cheaper than paid, builds community | G7: Needs existing member base first, slower to scale
A8: SMS Marketing | B8: 15 | C8: 0.15 | D8: 100 | E8: 100000 | F8: High open rates (98%), direct communication, $0.015/message | G8: Needs opt-in list first, compliance (CASL), limited for cold outreach
A9: Community Partnerships | B9: 10 | C9: 0.35 | D9: 29 | E9: 29000 | F9: Trust transfer, reaches target market directly, low cost | G9: Time intensive to build, variable results, not scalable initially
A10: TikTok/Instagram Reels | B10: 18 | C10: 0.2 | D10: 90 | E10: 90000 | F10: Lower CPM, younger demographic, viral potential | G10: Less proven for financial services, content creation overhead
A13: RECOMMENDED STRATEGY: BLENDED APPROACH
A15: Channel | B15: % of Leads | C15: CPL | D15: Monthly Cost | E15: Why
A16: Facebook Ads (Primary) | B16: 0.5 | C16: 22 | D16: 44000 | E16: Scalable, proven for financial services
A17: Member Referrals | B17: 0.3 | C17: 25 | D17: 15000 | E17: Highest quality, lowest cost per member
A18: Community Partnerships | B18: 0.2 | C18: 10 | D18: 5800 | E18: Trust-based, reaches target directly
A20: TOTAL BLENDED MONTHLY COST | D20: 64800
A21: BLENDED COST PER MEMBER | D21: 64.8

Sheet 12-Month P&L
A1: THE GUARDIAN - 12-MONTH P&L WITH LEAD GENERATION
A2: Ramping from 0 to 1,000 members/month acquisition | All figures in CAD
B4: M1 | C4: M2 | D4: M3 | E4: M4 | F4: M5 | G4: M6 | H4: M7 | I4: M8 | J4: M9 | K4: M10 | L4: M11 | M4: M12 | N4: YEAR 1
A5: NEW MEMBERS THIS MONTH | B5: 100 | C5: 200 | D5: 300 | E5: 400 | F5: 500 | G5: 600 | H5: 700 | I5: 800 | J5: 900 | K5: 1000 | L5: 1000 | M5: 1000 | N5: =SUM(B5:M5) -> 7500
A6: CUMULATIVE MEMBERS | B6: =B5 -> 100 | C6: =B6+C5 -> 300 | D6: =C6+D5 -> 600 | E6: =D6+E5 -> 1000 | F6: =E6+F5 -> 1500 | G6: =F6+G5 -> 2100 | H6: =G6+H5 -> 2800 | I6: =H6+I5 -> 3600 | J6: =I6+J5 -> 4500 | ... M6: =L6+M5 -> 7500 | N6: =M6 -> 7500
A8: REVENUE
A9: Basic Subscriptions | B9: =B6*Assumptions!$B$6*Assumptions!$B$8*Assumptions!$B$10 -> 1136.625 | C9: =C6*Assumptions!$B$6*Assumptions!$B$8*Assumptions!$B$10 -> 3409.875 | D9: =D6*Assumptions!$B$6*Assumptions!$B$8*Assumptions!$B$10 -> 6819.75 | E9: =E6*Assumptions!$B$6*Assumptions!$B$8*Assumptions!$B$10 -> 11366.25 | F9: =F6*Assumptions!$B$6*Assumptions!$B$8*Assumptions!$B$10 -> 17049.375 | G9: =G6*Assumptions!$B$6*Assumptions!$B$8*Assumptions!$B$10 -> 23869.125 | H9: =H6*Assumptions!$B$6*Assumptions!$B$8*Assumptions!$B$10 -> 31825.5 | I9: =I6*Assumptions!$B$6*Assumptions!$B$8*Assumptions!$B$10 -> 40918.5 | ... M9: =M6*Assumptions!$B$6*Assumptions!$B$8*Assumptions!$B$10 -> 85246.875 | N9: =SUM(B9:M9) -> 409185
A10: Elite Subscriptions | B10: =B6*Assumptions!$B$7*Assumptions!$B$9*Assumptions!$B$10 -> 772.905 | C10: =C6*Assumptions!$B$7*Assumptions!$B$9*Assumptions!$B$10 -> 2318.715 | D10: =D6*Assumptions!$B$7*Assumptions!$B$9*Assumptions!$B$10 -> 4637.43 | E10: =E6*Assumptions!$B$7*Assumptions!$B$9*Assumptions!$B$10 -> 7729.05 | F10: =F6*Assumptions!$B$7*Assumptions!$B$9*Assumptions!$B$10 -> 11593.575 | G10: =G6*Assumptions!$B$7*Assumptions!$B$9*Assumptions!$B$10 -> 16231.005 | H10: =H6*Assumptions!$B$7*Assumptions!$B$9*Assumptions!$B$10 -> 21641.34 | I10: =I6*Assumptions!$B$7*Assumptions!$B$9*Assumptions!$B$10 -> 27824.58 | ... M10: =M6*Assumptions!$B$7*Assumptions!$B$9*Assumptions!$B$10 -> 57967.875 | N10: =SUM(B10:M10) -> 278245.8
A11: Payroll Accelerator ($2.50) | B11: =B6*Assumptions!$B$21*2.5 -> 75 | C11: =C6*Assumptions!$B$21*2.5 -> 225 | D11: =D6*Assumptions!$B$21*2.5 -> 450 | E11: =E6*Assumptions!$B$21*2.5 -> 750 | F11: =F6*Assumptions!$B$21*2.5 -> 1125 | G11: =G6*Assumptions!$B$21*2.5 -> 1575 | H11: =H6*Assumptions!$B$21*2.5 -> 2100 | I11: =I6*Assumptions!$B$21*2.5 -> 2700 | ... M11: =M6*Assumptions!$B$21*2.5 -> 5625 | N11: =SUM(B11:M11) -> 27000
A12: Check Bridge ($2.50) | B12: =B6*Assumptions!$B$22*2.5 -> 37.5 | C12: =C6*Assumptions!$B$22*2.5 -> 112.5 | D12: =D6*Assumptions!$B$22*2.5 -> 225 | E12: =E6*Assumptions!$B$22*2.5 -> 375 | F12: =F6*Assumptions!$B$22*2.5 -> 562.5 | G12: =G6*Assumptions!$B$22*2.5 -> 787.5 | H12: =H6*Assumptions!$B$22*2.5 -> 1050 | I12: =I6*Assumptions!$B$22*2.5 -> 1350 | ... M12: =M6*Assumptions!$B$22*2.5 -> 2812.5 | N12: =SUM(B12:M12) -> 13500
A13: Milk Money Interest | B13: =B6*Assumptions!$B$20*Assumptions!$B$27*Assumptions!$B$28*(Assumptions!$B$29/365) -> 13.739178 | C13: =C6*Assumptions!$B$20*Assumptions!$B$27*Assumptions!$B$28*(Assumptions!$B$29/365) -> 41.217534 | D13: =D6*Assumptions!$B$20*Assumptions!$B$27*Assumptions!$B$28*(Assumptions!$B$29/365) -> 82.435068 | E13: =E6*Assumptions!$B$20*Assumptions!$B$27*Assumptions!$B$28*(Assumptions!$B$29/365) -> 137.39178 | F13: =F6*Assumptions!$B$20*Assumptions!$B$27*Assumptions!$B$28*(Assumptions!$B$29/365) -> 206.08767 | G13: =G6*Assumptions!$B$20*Assumptions!$B$27*Assumptions!$B$28*(Assumptions!$B$29/365) -> 288.52274 | H13: =H6*Assumptions!$B$20*Assumptions!$B$27*Assumptions!$B$28*(Assumptions!$B$29/365) -> 384.69699 | I13: =I6*Assumptions!$B$20*Assumptions!$B$27*Assumptions!$B$28*(Assumptions!$B$29/365) -> 494.61041 | ... M13: =M6*Assumptions!$B$20*Assumptions!$B$27*Assumptions!$B$28*(Assumptions!$B$29/365) -> 1030.4384 | N13: =SUM(B13:M13) -> 4946.1041
A14: Lifeline Link Net | B14: =B6*Assumptions!$B$23*1 -> 10 | C14: =C6*Assumptions!$B$23*1 -> 30 | D14: =D6*Assumptions!$B$23*1 -> 60 | E14: =E6*Assumptions!$B$23*1 -> 100 | F14: =F6*Assumptions!$B$23*1 -> 150 | G14: =G6*Assumptions!$B$23*1 -> 210 | H14: =H6*Assumptions!$B$23*1 -> 280 | I14: =I6*Assumptions!$B$23*1 -> 360 | ... M14: =M6*Assumptions!$B$23*1 -> 750 | N14: =SUM(B14:M14) -> 3600
A15: Nickel Millionaire Pool | B15: =B6*Assumptions!$B$24*0.05 -> 125 | C15: =C6*Assumptions!$B$24*0.05 -> 375 | D15: =D6*Assumptions!$B$24*0.05 -> 750 | E15: =E6*Assumptions!$B$24*0.05 -> 1250 | F15: =F6*Assumptions!$B$24*0.05 -> 1875 | G15: =G6*Assumptions!$B$24*0.05 -> 2625 | H15: =H6*Assumptions!$B$24*0.05 -> 3500 | I15: =I6*Assumptions!$B$24*0.05 -> 4500 | ... M15: =M6*Assumptions!$B$24*0.05 -> 9375 | N15: =SUM(B15:M15) -> 45000
A16: TOTAL REVENUE | B16: =SUM(B9:B15) -> 2170.7692 | C16: =SUM(C9:C15) -> 6512.3075 | D16: =SUM(D9:D15) -> 13024.615 | E16: =SUM(E9:E15) -> 21707.692 | F16: =SUM(F9:F15) -> 32561.538 | G16: =SUM(G9:G15) -> 45586.153 | H16: =SUM(H9:H15) -> 60781.537 | I16: =SUM(I9:I15) -> 78147.69 | ... N16: =SUM(N9:N15) -> 781476.9
A18: ZŪM RAILS COSTS
A19: Shield Aggregation | B19: =B6*Assumptions!$B$19*Assumptions!$B$16 -> 24 | C19: =C6*Assumptions!$B$19*Assumptions!$B$16 -> 72 | D19: =D6*Assumptions!$B$19*Assumptions!$B$16 -> 144 | E19: =E6*Assumptions!$B$19*Assumptions!$B$16 -> 240 | F19: =F6*Assumptions!$B$19*Assumptions!$B$16 -> 360 | G19: =G6*Assumptions!$B$19*Assumptions!$B$16 -> 504 | H19: =H6*Assumptions!$B$19*Assumptions!$B$16 -> 672 | I19: =I6*Assumptions!$B$19*Assumptions!$B$16 -> 864 | ... M19: =M6*Assumptions!$B$19*Assumptions!$B$16 -> 1800 | N19: =SUM(B19:M19) -> 8640
A20: Milk Money (EFT+Interac) | B20: =B6*Assumptions!$B$20*(Assumptions!$B$13+Assumptions!$B$14) -> 75 | C20: =C6*Assumptions!$B$20*(Assumptions!$B$13+Assumptions!$B$14) -> 225 | D20: =D6*Assumptions!$B$20*(Assumptions!$B$13+Assumptions!$B$14) -> 450 | E20: =E6*Assumptions!$B$20*(Assumptions!$B$13+Assumptions!$B$14) -> 750 | F20: =F6*Assumptions!$B$20*(Assumptions!$B$13+Assumptions!$B$14) -> 1125 | G20: =G6*Assumptions!$B$20*(Assumptions!$B$13+Assumptions!$B$14) -> 1575 | H20: =H6*Assumptions!$B$20*(Assumptions!$B$13+Assumptions!$B$14) -> 2100 | I20: =I6*Assumptions!$B$20*(Assumptions!$B$13+Assumptions!$B$14) -> 2700 | ... M20: =M6*Assumptions!$B$20*(Assumptions!$B$13+Assumptions!$B$14) -> 5625 | N20: =SUM(B20:M20) -> 27000
A21: Payroll Accelerator (ANR) | B21: =B6*Assumptions!$B$21*Assumptions!$B$15 -> 37.5 | C21: =C6*Assumptions!$B$21*Assumptions!$B$15 -> 112.5 | D21: =D6*Assumptions!$B$21*Assumptions!$B$15 -> 225 | E21: =E6*Assumptions!$B$21*Assumptions!$B$15 -> 375 | F21: =F6*Assumptions!$B$21*Assumptions!$B$15 -> 562.5 | G21: =G6*Assumptions!$B$21*Assumptions!$B$15 -> 787.5 | H21: =H6*Assumptions!$B$21*Assumptions!$B$15 -> 1050 | I21: =I6*Assumptions!$B$21*Assumptions!$B$15 -> 1350 | ... M21: =M6*Assumptions!$B$21*Assumptions!$B$15 -> 2812.5 | N21: =SUM(B21:M21) -> 13500
A22: Check Bridge (EFT+Interac) | B22: =B6*Assumptions!$B$22*(Assumptions!$B$13+Assumptions!$B$14) -> 18.75 | C22: =C6*Assumptions!$B$22*(Assumptions!$B$13+Assumptions!$B$14) -> 56.25 | D22: =D6*Assumptions!$B$22*(Assumptions!$B$13+Assumptions!$B$14) -> 112.5 | E22: =E6*Assumptions!$B$22*(Assumptions!$B$13+Assumptions!$B$14) -> 187.5 | F22: =F6*Assumptions!$B$22*(Assumptions!$B$13+Assumptions!$B$14) -> 281.25 | G22: =G6*Assumptions!$B$22*(Assumptions!$B$13+Assumptions!$B$14) -> 393.75 | H22: =H6*Assumptions!$B$22*(Assumptions!$B$13+Assumptions!$B$14) -> 525 | I22: =I6*Assumptions!$B$22*(Assumptions!$B$13+Assumptions!$B$14) -> 675 | ... M22: =M6*Assumptions!$B$22*(Assumptions!$B$13+Assumptions!$B$14) -> 1406.25 | N22: =SUM(B22:M22) -> 6750
A23: Lifeline Link (Interac) | B23: =B6*Assumptions!$B$23*Assumptions!$B$14 -> 10 | C23: =C6*Assumptions!$B$23*Assumptions!$B$14 -> 30 | D23: =D6*Assumptions!$B$23*Assumptions!$B$14 -> 60 | E23: =E6*Assumptions!$B$23*Assumptions!$B$14 -> 100 | F23: =F6*Assumptions!$B$23*Assumptions!$B$14 -> 150 | G23: =G6*Assumptions!$B$23*Assumptions!$B$14 -> 210 | H23: =H6*Assumptions!$B$23*Assumptions!$B$14 -> 280 | I23: =I6*Assumptions!$B$23*Assumptions!$B$14 -> 360 | ... M23: =M6*Assumptions!$B$23*Assumptions!$B$14 -> 750 | N23: =SUM(B23:M23) -> 3600
A24: Nickel Millionaire (pool) | B24: =B6*Assumptions!$B$24*0.05 -> 125 | C24: =C6*Assumptions!$B$24*0.05 -> 375 | D24: =D6*Assumptions!$B$24*0.05 -> 750 | E24: =E6*Assumptions!$B$24*0.05 -> 1250 | F24: =F6*Assumptions!$B$24*0.05 -> 1875 | G24: =G6*Assumptions!$B$24*0.05 -> 2625 | H24: =H6*Assumptions!$B$24*0.05 -> 3500 | I24: =I6*Assumptions!$B$24*0.05 -> 4500 | ... M24: =M6*Assumptions!$B$24*0.05 -> 9375 | N24: =SUM(B24:M24) -> 45000
A25: New User Aggregation | B25: =B5*0.1*Assumptions!$B$16 -> 3 | C25: =C5*0.1*Assumptions!$B$16 -> 6 | D25: =D5*0.1*Assumptions!$B$16 -> 9 | E25: =E5*0.1*Assumptions!$B$16 -> 12 | F25: =F5*0.1*Assumptions!$B$16 -> 15 | G25: =G5*0.1*Assumptions!$B$16 -> 18 | H25: =H5*0.1*Assumptions!$B$16 -> 21 | I25: =I5*0.1*Assumptions!$B$16 -> 24 | ... M25: =M5*0.1*Assumptions!$B$16 -> 30 | N25: =SUM(B25:M25) -> 225
A26: TOTAL ZŪM RAILS | B26: =SUM(B19:B25) -> 293.25 | C26: =SUM(C19:C25) -> 876.75 | D26: =SUM(D19:D25) -> 1750.5 | E26: =SUM(E19:E25) -> 2914.5 | F26: =SUM(F19:F25) -> 4368.75 | G26: =SUM(G19:G25) -> 6113.25 | H26: =SUM(H19:H25) -> 8148 | I26: =SUM(I19:I25) -> 10473 | ... N26: =SUM(N19:N25) -> 104715
A28: PRIVATE BANKER COSTS
A29: Agent Salaries | B29: =ROUNDUP(B6/Assumptions!$B$34,0)*Assumptions!$B$33 -> 1000 | C29: =ROUNDUP(C6/Assumptions!$B$34,0)*Assumptions!$B$33 -> 2000 | D29: =ROUNDUP(D6/Assumptions!$B$34,0)*Assumptions!$B$33 -> 3000 | E29: =ROUNDUP(E6/Assumptions!$B$34,0)*Assumptions!$B$33 -> 5000 | F29: =ROUNDUP(F6/Assumptions!$B$34,0)*Assumptions!$B$33 -> 8000 | G29: =ROUNDUP(G6/Assumptions!$B$34,0)*Assumptions!$B$33 -> 11000 | H29: =ROUNDUP(H6/Assumptions!$B$34,0)*Assumptions!$B$33 -> 14000 | I29: =ROUNDUP(I6/Assumptions!$B$34,0)*Assumptions!$B$33 -> 18000 | ... M29: =ROUNDUP(M6/Assumptions!$B$34,0)*Assumptions!$B$33 -> 38000 | N29: =SUM(B29:M29) -> 184000
A30: Agent Training (new hires) | B30: =MAX(0,ROUNDUP(B6/Assumptions!$B$34,0)-0)*Assumptions!$B$35 -> 500 | C30: =MAX(0,ROUNDUP(C6/Assumptions!$B$34,0)-ROUNDUP(B6/Assumptions!$B$34,0))*Assumptions!$B$35 -> 500 | D30: =MAX(0,ROUNDUP(D6/Assumptions!$B$34,0)-ROUNDUP(C6/Assumptions!$B$34,0))*Assumptions!$B$35 -> 500 | E30: =MAX(0,ROUNDUP(E6/Assumptions!$B$34,0)-ROUNDUP(D6/Assumptions!$B$34,0))*Assumptions!$B$35 -> 1000 | F30: =MAX(0,ROUNDUP(F6/Assumptions!$B$34,0)-ROUNDUP(E6/Assumptions!$B$34,0))*Assumptions!$B$35 -> 1500 | G30: =MAX(0,ROUNDUP(G6/Assumptions!$B$34,0)-ROUNDUP(F6/Assumptions!$B$34,0))*Assumptions!$B$35 -> 1500 | H30: =MAX(0,ROUNDUP(H6/Assumptions!$B$34,0)-ROUNDUP(G6/Assumptions!$B$34,0))*Assumptions!$B$35 -> 1500 | I30: =MAX(0,ROUNDUP(I6/Assumptions!$B$34,0)-ROUNDUP(H6/Assumptions!$B$34,0))*Assumptions!$B$35 -> 2000 | J30: =MAX(0,ROUNDUP(J6/Assumptions!$B$34,0)-ROUNDUP(I6/Assumptions!$B$34,0))*Assumptions!$B$35 -> 2500 | ... M30: =MAX(0,ROUNDUP(M6/Assumptions!$B$34,0)-ROUNDUP(L6/Assumptions!$B$34,0))*Assumptions!$B$35 -> 2500 | N30: =SUM(B30:M30) -> 19000
A31: TOTAL PRIVATE BANKER | B31: =SUM(B29:B30) -> 1500 | C31: =SUM(C29:C30) -> 2500 | D31: =SUM(D29:D30) -> 3500 | E31: =SUM(E29:E30) -> 6000 | F31: =SUM(F29:F30) -> 9500 | G31: =SUM(G29:G30) -> 12500 | H31: =SUM(H29:H30) -> 15500 | I31: =SUM(I29:I30) -> 20000 | ... N31: =SUM(N29:N30) -> 203000
A33: LEAD GENERATION COSTS
A34: Facebook Ads (50% of leads) | B34: =B5*0.5/Assumptions!$B$44*Assumptions!$B$46 -> 4400 | C34: =C5*0.5/Assumptions!$B$44*Assumptions!$B$46 -> 8800 | D34: =D5*0.5/Assumptions!$B$44*Assumptions!$B$46 -> 13200 | E34: =E5*0.5/Assumptions!$B$44*Assumptions!$B$46 -> 17600 | F34: =F5*0.5/Assumptions!$B$44*Assumptions!$B$46 -> 22000 | G34: =G5*0.5/Assumptions!$B$44*Assumptions!$B$46 -> 26400 | H34: =H5*0.5/Assumptions!$B$44*Assumptions!$B$46 -> 30800 | I34: =I5*0.5/Assumptions!$B$44*Assumptions!$B$46 -> 35200 | ... M34: =M5*0.5/Assumptions!$B$44*Assumptions!$B$46 -> 44000 | N34: =SUM(B34:M34) -> 330000
A35: Referral Bonuses (30%) | B35: =B5*0.3*Assumptions!$B$47 -> 300 | C35: =C5*0.3*Assumptions!$B$47 -> 600 | D35: =D5*0.3*Assumptions!$B$47 -> 900 | E35: =E5*0.3*Assumptions!$B$47 -> 1200 | F35: =F5*0.3*Assumptions!$B$47 -> 1500 | G35: =G5*0.3*Assumptions!$B$47 -> 1800 | H35: =H5*0.3*Assumptions!$B$47 -> 2100 | I35: =I5*0.3*Assumptions!$B$47 -> 2400 | ... M35: =M5*0.3*Assumptions!$B$47 -> 3000 | N35: =SUM(B35:M35) -> 22500
A36: Community Partnerships (20%) | B36: =B5*0.2/Assumptions!$B$44*10 -> 800 | C36: =C5*0.2/Assumptions!$B$44*10 -> 1600 | D36: =D5*0.2/Assumptions!$B$44*10 -> 2400 | E36: =E5*0.2/Assumptions!$B$44*10 -> 3200 | F36: =F5*0.2/Assumptions!$B$44*10 -> 4000 | G36: =G5*0.2/Assumptions!$B$44*10 -> 4800 | H36: =H5*0.2/Assumptions!$B$44*10 -> 5600 | I36: =I5*0.2/Assumptions!$B$44*10 -> 6400 | ... M36: =M5*0.2/Assumptions!$B$44*10 -> 8000 | N36: =SUM(B36:M36) -> 60000
A37: TOTAL LEAD GENERATION | B37: =SUM(B34:B36) -> 5500 | C37: =SUM(C34:C36) -> 11000 | D37: =SUM(D34:D36) -> 16500 | E37: =SUM(E34:E36) -> 22000 | F37: =SUM(F34:F36) -> 27500 | G37: =SUM(G34:G36) -> 33000 | H37: =SUM(H34:H36) -> 38500 | I37: =SUM(I34:I36) -> 44000 | ... N37: =SUM(N34:N36) -> 412500
A39: OTHER OPERATING COSTS
A40: Milk Money Bad Debt | B40: =B6*Assumptions!$B$20*Assumptions!$B$27*Assumptions!$B$30 -> 288 | C40: =C6*Assumptions!$B$20*Assumptions!$B$27*Assumptions!$B$30 -> 864 | D40: =D6*Assumptions!$B$20*Assumptions!$B$27*Assumptions!$B$30 -> 1728 | E40: =E6*Assumptions!$B$20*Assumptions!$B$27*Assumptions!$B$30 -> 2880 | F40: =F6*Assumptions!$B$20*Assumptions!$B$27*Assumptions!$B$30 -> 4320 | G40: =G6*Assumptions!$B$20*Assumptions!$B$27*Assumptions!$B$30 -> 6048 | H40: =H6*Assumptions!$B$20*Assumptions!$B$27*Assumptions!$B$30 -> 8064 | I40: =I6*Assumptions!$B$20*Assumptions!$B$27*Assumptions!$B$30 -> 10368 | ... M40: =M6*Assumptions!$B$20*Assumptions!$B$27*Assumptions!$B$30 -> 21600 | N40: =SUM(B40:M40) -> 103680
A41: Tech Infrastructure | B41: =Assumptions!$B$38 -> 1500 | C41: =Assumptions!$B$38 -> 1500 | D41: =Assumptions!$B$38 -> 1500 | E41: =Assumptions!$B$38 -> 1500 | F41: =Assumptions!$B$38 -> 1500 | G41: =Assumptions!$B$38 -> 1500 | H41: =Assumptions!$B$38 -> 1500 | I41: =Assumptions!$B$38 -> 1500 | ... M41: =Assumptions!$B$38 -> 1500 | N41: =SUM(B41:M41) -> 18000
A42: Compliance & Legal | B42: =Assumptions!$B$39 -> 500 | C42: =Assumptions!$B$39 -> 500 | D42: =Assumptions!$B$39 -> 500 | E42: =Assumptions!$B$39 -> 500 | F42: =Assumptions!$B$39 -> 500 | G42: =Assumptions!$B$39 -> 500 | H42: =Assumptions!$B$39 -> 500 | I42: =Assumptions!$B$39 -> 500 | ... M42: =Assumptions!$B$39 -> 500 | N42: =SUM(B42:M42) -> 6000
A43: Customer Support | B43: =Assumptions!$B$40 -> 300 | C43: =Assumptions!$B$40 -> 300 | D43: =Assumptions!$B$40 -> 300 | E43: =Assumptions!$B$40 -> 300 | F43: =Assumptions!$B$40 -> 300 | G43: =Assumptions!$B$40 -> 300 | H43: =Assumptions!$B$40 -> 300 | I43: =Assumptions!$B$40 -> 300 | ... M43: =Assumptions!$B$40 -> 300 | N43: =SUM(B43:M43) -> 3600
A44: TOTAL OTHER COSTS | B44: =SUM(B40:B43) -> 2588 | C44: =SUM(C40:C43) -> 3164 | D44: =SUM(D40:D43) -> 4028 | E44: =SUM(E40:E43) -> 5180 | F44: =SUM(F40:F43) -> 6620 | G44: =SUM(G40:G43) -> 8348 | H44: =SUM(H40:H43) -> 10364 | I44: =SUM(I40:I43) -> 12668 | ... N44: =SUM(N40:N43) -> 131280
A46: TOTAL COSTS | B46: =B26+B31+B37+B44 -> 9881.25 | C46: =C26+C31+C37+C44 -> 17540.75 | D46: =D26+D31+D37+D44 -> 25778.5 | E46: =E26+E31+E37+E44 -> 36094.5 | F46: =F26+F31+F37+F44 -> 47988.75 | G46: =G26+G31+G37+G44 -> 59961.25 | H46: =H26+H31+H37+H44 -> 72512 | I46: =I26+I31+I37+I44 -> 87141 | ... N46: =N26+N31+N37+N44 -> 851495
A48: NET OPERATING INCOME | B48: =B16-B46 -> -7710.4808 | C48: =C16-C46 -> -11028.442 | D48: =D16-D46 -> -12753.885 | E48: =E16-E46 -> -14386.808 | F48: =F16-F46 -> -15427.212 | G48: =G16-G46 -> -14375.097 | H48: =H16-H46 -> -11730.463 | I48: =I16-I46 -> -8993.3096 | ... N48: =N16-N46 -> -70018.096
...

Sheet Cost Breakdown Chart
A1: FOR EVERY $1.00 OF REVENUE - WHERE DOES IT GO?
A2: The Guardian MVP | Year 1 with Lead Generation
A5: Category | B5: Amount | C5: Cents per $1
A6: PROFIT (You Keep) | B6: ='12-Month P&L'!N48 -> -70018.096 | C6: =B6/'12-Month P&L'!N16*100 -> -8.959714
A7: Lead Generation | B7: ='12-Month P&L'!N37 -> 412500 | C7: =B7/'12-Month P&L'!N16*100 -> 52.784669
A8: Private Bankers | B8: ='12-Month P&L'!N31 -> 203000 | C8: =B8/'12-Month P&L'!N16*100 -> 25.976455
A9: Zūm Rails | B9: ='12-Month P&L'!N26 -> 104715 | C9: =B9/'12-Month P&L'!N16*100 -> 13.399628
A10: Bad Debt | B10: ='12-Month P&L'!N40 -> 103680 | C10: =B10/'12-Month P&L'!N16*100 -> 13.267187
A11: Operations | B11: ='12-Month P&L'!N41+'12-Month P&L'!N42+'12-Month P&L'!N43 -> 27600 | C11: =B11/'12-Month P&L'!N16*100 -> 3.5317742
A14: SUMMARY
A16: Total Revenue (Year 1) | B16: ='12-Month P&L'!N16 -> 781476.9
A17: Total Costs (Year 1) | B17: ='12-Month P&L'!N46 -> 851495
A18: Net Operating Income | B18: ='12-Month P&L'!N48 -> -70018.096
A19: Operating Margin | B19: ='12-Month P&L'!N49 -> -0.08959714
A21: Cost per Member Acquired | B21: ='12-Month P&L'!N37/SUM('12-Month P&L'!B5:M5) -> 55
A22: Total Members Acquired | B22: =SUM('12-Month P&L'!B5:M5) -> 7500

Sheet Summary
A1: THE GUARDIAN MVP - COMPLETE FINANCIAL SUMMARY
A2: With Lead Generation Costs Included
A4: THE BOTTOM LINE
A6: Total Revenue (Year 1) | B6: ='12-Month P&L'!N16 -> 781476.9
A7: Total Costs (Year 1) | B7: ='12-Month P&L'!N46 -> 851495
A8: Net Operating Income | B8: ='12-Month P&L'!N48 -> -70018.096
A9: Operating Margin | B9: ='12-Month P&L'!N49 -> -0.08959714
A11: Members Acquired (Year 1) | B11: =SUM('12-Month P&L'!B5:M5) -> 7500
A12: End-of-Year Member Count | B12: ='12-Month P&L'!M6 -> 7500
A14: COST BREAKDOWN
A15: Lead Generation | B15: ='12-Month P&L'!N37 -> 412500 | C15: ='12-Month P&L'!N37/'12-Month P&L'!N46 -> 0.48444207
A16: Private Bankers | B16: ='12-Month P&L'!N31 -> 203000 | C16: ='12-Month P&L'!N31/'12-Month P&L'!N46 -> 0.23840422
A17: Zūm Rails | B17: ='12-Month P&L'!N26 -> 104715 | C17: ='12-Month P&L'!N26/'12-Month P&L'!N46 -> 0.12297782
A18: Bad Debt | B18: ='12-Month P&L'!N40 -> 103680 | C18: ='12-Month P&L'!N40/'12-Month P&L'!N46 -> 0.12176231
A19: Operations | B19: ='12-Month P&L'!N41+'12-Month P&L'!N42+'12-Month P&L'!N43 -> 27600 | C19: =('12-Month P&L'!N41+'12-Month P&L'!N42+'12-Month P&L'!N43)/'12-Month P&L'!N46 -> 0.032413578
A21: UNIT ECONOMICS
A22: Cost per Member Acquired | B22: ='12-Month P&L'!N37/SUM('12-Month P&L'!B5:M5) -> 55
A23: Annual Revenue per Member | B23: ='12-Month P&L'!N16/'12-Month P&L'!M6 -> 104.19692
A24: Annual Cost per Member | B24: ='12-Month P&L'!N46/'12-Month P&L'!M6 -> 113.53267
A25: Annual Profit per Member | B25: ='12-Month P&L'!N48/'12-Month P&L'!M6 -> -9.3357461
A28: VERDICT
A29: Is MVP Profitable? | B29: =IF('12-Month P&L'!N48>0,"YES - PROFITABLE","NO - LOSS") -> NO - LOSS
